Workbook

Sheet Version
A1: BANCO DE PREGUNTAS · SOLARIS MERIT NEIVA
A2: Versión del banco | B2: 2026.09.26-n
A3: Fecha de generación | B3: 2026-09-26
A4: Huella de contenido | B4: 95953e8a9d
A6: Preguntas del banco principal | B6: 626
A7: Casos del banco principal | B7: 214
A8: Preguntas del banco de repaso | B8: 291
A9: Situaciones comportamentales activas | B9: 138
A11: Ventaja de longitud de la correcta · principal | B11: -3 caracteres
A12: Ventaja de longitud de la correcta · repaso | B12: +35 caracteres
A14: Cómo verificar que tiene la última versión
A15: 1. Compare la huella de contenido con la que reporta la app en la tarjeta del banco.
A16: 2. Si coinciden, está usando el mismo archivo. Si no, actualice el Excel del repositorio.
A17: 3. La versión de sw.js es otra cosa: controla la caché del celular, no el contenido del banco.
A18: Preguntas de aptitudes para práctica (hoja Basicas) | B18: 114
A19: La hoja Basicas trae solo aptitudes (lectura, cálculo, análisis, ofimática): son práctica y no entran en el ponderado.
A20: Filas inactivas que se conservan en el archivo (comportamentales): 30
A21: Las filas con activa = NO no se usan en los simulacros; se conservan por historia y se pueden reactivar.

Sheet Funcionales
A1: id | B1: concurso | C1: eje | D1: nivel | E1: caso_id | F1: caso | G1: texto_caso | H1: enunciado | I1: a | J1: b | K1: c | L1: respuesta | M1: explicacion | N1: porque_no | O1: fuente | P1: activa | Q1: dificultad | R1: tipo_v2
A2: F0001 | B2: PS 2782 de 2026 - ESE 2 - HUHMP Neiva | C2: Sistema de salud y Ley 100 de 1993 | D2: Profesional | E2: C001 | F2: Caso 001 | G2: La E.S.E. recibe un derecho de petición de un ciudadano que afirma que, por ser el hospital una entidad pública, toda su contratación debe adelantarse por licitación pública de la Ley 80 de 1993. El jefe de la oficina jurídica pide concepto. | H2: ¿Cuál es el régimen contractual aplicable a la E.S.E.? | I2: El derecho privado, pudiendo incluir discrecionalmente las cláusulas excepcionales | J2: El Estatuto General de Contratación de la Administración Pública, sin excepciones | K2: El régimen de las empresas industriales y comerciales del Estado del orden nacional | L2: a | M2: El numeral 6 del artículo 195 de la Ley 100 de 1993 dispone que en materia contractual las E.S.E. se rigen por el derecho privado, con la posibilidad de pactar discrecionalmente las cláusulas excepcionales. | N2: «El Estatuto General de Contratación de…» desconoce el régimen exceptuado del artículo 195.6; «El régimen de las empresas industriales…» traslada un régimen que la ley no previó para las E.S.E., que son una categoría especial de entidad pública descentralizada. | O2: Ley 100 de 1993, art. 195 num. 6 | P2: SI | Q2: Basica | R2: repaso
A3: F0002 | B3: PS 2782 de 2026 - ESE 2 - HUHMP Neiva | C3: Sistema de salud y Ley 100 de 1993 | D3: Profesional | E3: C001 | F3: Caso 001 | G3: La E.S.E. recibe un derecho de petición de un ciudadano que afirma que, por ser el hospital una entidad pública, toda su contratación debe adelantarse por licitación pública de la Ley 80 de 1993. El jefe de la oficina jurídica pide concepto. | H3: El ciudadano insiste en que, al aplicar derecho privado, la E.S.E. queda libre de los principios de la función administrativa. La respuesta correcta es: | I3: Es cierto: el régimen privado excluye los principios del artículo 209 de la Constitución | J3: Los principios de la función administrativa y de la gestión fiscal siguen aplicando a la actividad contractual | K3: Solo aplican los principios cuando el contrato supere la menor cuantía | L3: b | M3: El artículo 13 de la Ley 1150 de 2007 obliga a las entidades con régimen contractual excepcional a aplicar los principios de la función administrativa y de la gestión fiscal de los artículos 209 y 267 de la Constitución. | N3: «Es cierto: el régimen privado excluye…» y «Solo aplican los principios cuando el…» confunden el régimen sustantivo aplicable con la naturaleza pública de los recursos y de la función, que no admite excepción por cuantía. | O3: Ley 1150 de 2007, art. 13; C.P. arts. 209 y 267 | P3: SI | Q3: Basica | R3: repaso
A4: F0003 | B4: PS 2782 de 2026 - ESE 2 - HUHMP Neiva | C4: Sistema de salud y Ley 100 de 1993 | D4: Profesional | E4: C001 | F4: Caso 001 | G4: La E.S.E. recibe un derecho de petición de un ciudadano que afirma que, por ser el hospital una entidad pública, toda su contratación debe adelantarse por licitación pública de la Ley 80 de 1993. El jefe de la oficina jurídica pide concepto. | H4: Sobre la naturaleza jurídica de la E.S.E., lo correcto es afirmar que: | I4: Es una sociedad de economía mixta sujeta al control de la Superintendencia de Sociedades | J4: Es un establecimiento público del orden nacional adscrito al Ministerio de Salud | K4: Es una categoría especial de entidad pública descentralizada, con personería jurídica, patrimonio propio y autonomía administrativa | L4: c | M4: El artículo 194 de la Ley 100 de 1993 define a las E.S.E. como categoría especial de entidad pública descentralizada, con personería jurídica, patrimonio propio y autonomía administrativa. | N4: «Es un establecimiento público del orden…» y «Es una sociedad de economía mixta…» asignan naturalezas y controles que no corresponden: la E.S.E. departamental se crea por ordenanza y es vigilada por la Superintendencia Nacional de Salud. | O4: Ley 100 de 1993, art. 194; Decreto 1876 de 1994 | P4: SI | Q4: Basica | R4: repaso
A5: F0004 | B5: PS 2782 de 2026 - ESE 2 - HUHMP Neiva | C5: Sistema de salud y Ley 100 de 1993 | D5: Profesional | E5: C002 | F5: Caso 002 | G5: En una mesa de trabajo sobre facturación, un contratista sostiene que el hospital puede cobrar copagos a un usuario del régimen subsidiado clasificado en el nivel I del Sisbén por una hospitalización. | H5: Frente a los pagos moderadores, lo correcto es: | I5: Toda la población afiliada paga cuotas moderadoras y copagos en igual proporción | J5: Los copagos son de libre fijación por cada prestador | K5: Los pagos moderadores se aplican según la capacidad socioeconómica del afiliado y existen servicios exceptuados | L5: c | M5: El artículo 187 de la Ley 100 de 1993 y sus normas reglamentarias establecen que los pagos moderadores se fijan según el ingreso o clasificación socioeconómica del afiliado, con servicios exceptuados de cobro. | N5: «Toda la población afiliada paga cuotas…» desconoce la progresividad legal; «Los copagos son de libre fijación…» confunde el cobro al usuario con la negociación tarifaria entre prestador y pagador. | O5: Ley 100 de 1993, art. 187 | P5: SI | Q5: Basica | R5: repaso
A6: F0005 | B6: PS 2782 de 2026 - ESE 2 - HUHMP Neiva | C6: Sistema de salud y Ley 100 de 1993 | D6: Profesional | E6: C002 | F6: Caso 002 | G6: En una mesa de trabajo sobre facturación, un contratista sostiene que el hospital puede cobrar copagos a un usuario del régimen subsidiado clasificado en el nivel I del Sisbén por una hospitalización. | H6: El usuario llega remitido y sin autorización de la EPS a urgencias. El hospital debe: | I6: Exigir la autorización antes de valorar al paciente | J6: Aplazar la atención hasta verificar la afiliación en el ADRES | K6: Prestar la atención inicial de urgencias sin exigir autorización previa ni pago | L6: c | M6: La atención inicial de urgencias es obligatoria y no puede condicionarse a autorización previa ni a pago, conforme a la Ley 100 y al artículo 14 de la Ley 1751 de 2015. | N6: «Exigir la autorización antes de valorar…» y «Aplazar la atención hasta verificar la…» condicionan una atención que la ley define como incondicionada; la verificación de derechos es un trámite posterior y administrativo. | O6: Ley 1751 de 2015, art. 14; Ley 100 de 1993, art. 168 | P6: SI | Q6: Basica | R6: repaso
A7: F0006 | B7: PS 2782 de 2026 - ESE 2 - HUHMP Neiva | C7: Sistema de salud y Ley 100 de 1993 | D7: Profesional | E7: C002 | F7: Caso 002 | G7: En una mesa de trabajo sobre facturación, un contratista sostiene que el hospital puede cobrar copagos a un usuario del régimen subsidiado clasificado en el nivel I del Sisbén por una hospitalización. | H7: Los recursos de la seguridad social en salud: | I7: Tienen destinación específica y no pueden destinarse ni utilizarse para fines distintos | J7: Pueden destinarse a gastos generales del departamento si hay superávit | K7: Pierden su destinación al ingresar al presupuesto de la E.S.E | L7: a | M7: El artículo 48 de la Constitución prohíbe destinar o utilizar los recursos de las instituciones de la seguridad social para fines diferentes a ella. | N7: «Pueden destinarse a gastos generales del…» y «Pierden su destinación al ingresar al…» suponen una pérdida de destinación que la Constitución no permite, cualquiera sea el momento presupuestal. | O7: C.P. art. 48; Ley 100 de 1993 | P7: SI | Q7: Basica | R7: repaso
A8: F0007 | B8: PS 2782 de 2026 - ESE 2 - HUHMP Neiva | C8: Sistema de salud y Ley 100 de 1993 | D8: Técnico | E8: C003 | F8: Caso 003 | G8: Un técnico de facturación debe explicar a un usuario nuevo la diferencia entre los regímenes del SGSSS y las rutas de afiliación. | H8: La afiliación al régimen subsidiado corresponde a: | I8: Población sin capacidad de pago identificada mediante la encuesta del Sisbén o listados censales | J8: Trabajadores dependientes con contrato laboral vigente | K8: Pensionados con mesada superior a dos salarios mínimos | L8: a | M8: El régimen subsidiado cubre a la población sin capacidad de pago, identificada mediante los instrumentos de focalización vigentes. | N8: «Trabajadores dependientes con contrato laboral vigente» y «Pensionados con mesada superior a dos…» describen afiliados cotizantes del régimen contributivo. | O8: Ley 100 de 1993, arts. 157 y 211 | P8: SI | Q8: Basica | R8: repaso
A9: F0008 | B9: PS 2782 de 2026 - ESE 2 - HUHMP Neiva | C9: Sistema de salud y Ley 100 de 1993 | D9: Técnico | E9: C003 | F9: Caso 003 | G9: Un técnico de facturación debe explicar a un usuario nuevo la diferencia entre los regímenes del SGSSS y las rutas de afiliación. | H9: El Sistema de Afiliación Transaccional (SAT) sirve para: | I9: Autorizar los medicamentos no financiados con la UPC | J9: Liquidar la nómina del personal asistencial | K9: Registrar y consultar en línea la afiliación y sus novedades | L9: c | M9: El SAT es el sistema dispuesto para el registro de la afiliación y el reporte de novedades de los afiliados al SGSSS. | N9: «Liquidar la nómina del personal asistencial» y «Autorizar los medicamentos no financiados con…» corresponden a procesos de talento humano y a trámites de prestaciones, ajenos al SAT. | O9: Decreto 780 de 2016, (Decreto Único Reglamentario del Sector Salud), Libro 2, Parte 1 | P9: SI | Q9: Basica | R9: repaso
A10: F0009 | B10: PS 2782 de 2026 - ESE 2 - HUHMP Neiva | C10: Sistema de salud y Ley 100 de 1993 | D10: Técnico | E10: C003 | F10: Caso 003 | G10: Un técnico de facturación debe explicar a un usuario nuevo la diferencia entre los regímenes del SGSSS y las rutas de afiliación. | H10: Si el usuario aparece como no afiliado y requiere atención no urgente, el trámite correcto es: | I10: Negar la atención y retirar al usuario | J10: Afiliarlo directamente el hospital a la EPS que elija el funcionario | K10: Orientarlo sobre la afiliación de oficio y la ruta con la entidad territorial, sin perjuicio de la atención que la ley ordena | L10: c | M10: El prestador orienta al usuario sobre la afiliación de oficio y la competencia de la entidad territorial, sin que ello afecte las atenciones obligatorias por ley. | N10: «Negar la atención y retirar al…» vulnera el deber de información y atención; «Afiliarlo directamente el hospital a la…» atribuye al prestador una facultad de afiliación que no tiene y desconoce la libre elección. | O10: Decreto 780 de 2016; Ley 1751 de 2015, art. 8 | P10: SI | Q10: Basica | R10: repaso
A11: F0010 | B11: PS 2782 de 2026 - ESE 2 - HUHMP Neiva | C11: Sistema de salud y Ley 100 de 1993 | D11: Profesional | E11: C004 | F11: Caso 004 | G11: La gerencia solicita un informe sobre el flujo de recursos y la contratación con las EPS para la vigencia. | H11: El giro directo a las IPS tiene como finalidad: | I11: Reemplazar la facturación del prestador | J11: Eliminar la auditoría de cuentas médicas | K11: Asegurar el flujo oportuno de recursos desde el pagador hacia el prestador | L11: c | M11: El giro directo busca garantizar el flujo y protección de los recursos hacia los prestadores, sin sustituir los procesos de facturación ni de auditoría. | N11: «Reemplazar la facturación del prestador» y «Eliminar la auditoría de cuentas médicas» suprimen procesos que se mantienen: facturar y auditar siguen siendo obligaciones de las partes. | O11: Ley 1438 de 2011; Decreto 780 de 2016, (Decreto Único Reglamentario del Sector Salud) | P11: SI | Q11: Basica | R11: repaso
A12: F0011 | B12: PS 2782 de 2026 - ESE 2 - HUHMP Neiva | C12: Sistema de salud y Ley 100 de 1993 | D12: Profesional | E12: C004 | F12: Caso 004 | G12: La gerencia solicita un informe sobre el flujo de recursos y la contratación con las EPS para la vigencia. | H12: Ante glosas de la EPS, el término y el trámite correctos son: | I12: El prestador debe aceptarlas todas para no afectar el flujo de caja | J12: Existe un procedimiento reglado de respuesta a glosas con términos definidos y conciliación posterior | K12: Las glosas solo se discuten ante el juez administrativo | L12: b | M12: El manual único de glosas fija el trámite y los términos para formularlas, responderlas y conciliarlas entre pagador y prestador. | N12: «El prestador debe aceptarlas todas para…» renuncia a derechos económicos del hospital; «Las glosas solo se discuten ante…» omite la etapa administrativa previa de respuesta y conciliación. | O12: Decreto 780 de 2016, (Decreto Único Reglamentario del Sector Salud); Resolución 3047 de 2008 y sus modificaciones | P12: SI | Q12: Basica | R12: repaso
... A115: F0114 | B115: PS 2782 de 2026 - ESE 2 - HUHMP Neiva | C115: Regimen disciplinario y CPACA | D115: Técnico | E115: C038 | F115: Caso 038 | G115: Un ciudadano radica una petición y la dependencia competente no responde dentro del término legal. | H115: La petición incompleta debe: | I115: Rechazarse de plano | J115: Requerirse al peticionario para que la complete, con las consecuencias legales si no lo hace | K115: Archivarse sin aviso | L115: b | M115: El artículo 17 del CPACA ordena requerir al peticionario para completar la petición, con desistimiento tácito si no atiende el requerimiento. | N115: «Rechazarse de plano» y «Archivarse sin aviso» niegan el derecho de petición sin agotar el requerimiento previo. | O115: Ley 1437 de 2011, art. 17 | P115: SI | Q115: Basica | R115: repaso
A116: F0115 | B116: PS 2782 de 2026 - ESE 2 - HUHMP Neiva | C116: Precision juridica del verbo | D116: Profesional | E116: C039 | F116: Caso 039 | G116: En la revisión de un proyecto de acto administrativo, la asesora observa que el documento usa indistintamente los verbos notificar, comunicar y publicar, y en otro aparte confunde revocar con anular. | H116: La diferencia correcta entre notificar, comunicar y publicar es: | I116: Notificar los actos particulares, comunicar los de trámite y publicar los generales | J116: Publicar los actos particulares, notificar los de trámite y comunicar los generales | K116: Comunicar los actos particulares, publicar los de trámite y notificar los generales | L116: a | M116: La notificación se reserva a los actos particulares y concretos, la comunicación a actos de trámite o a terceros interesados y la publicación a los actos de carácter general. | N116: «Publicar los actos particulares, notificar los…» y «Comunicar los actos particulares, publicar los…» intercambian los destinatarios: notificar es para los actos particulares, comunicar para los de trámite y publicar para los generales. | O116: Ley 1437 de 2011, arts. 65, 67 y 68 | P116: SI | Q116: Alta
A117: F0116 | B117: PS 2782 de 2026 - ESE 2 - HUHMP Neiva | C117: Precision juridica del verbo | D117: Profesional | E117: C039 | F117: Caso 039 | G117: En la revisión de un proyecto de acto administrativo, la asesora observa que el documento usa indistintamente los verbos notificar, comunicar y publicar, y en otro aparte confunde revocar con anular. | H117: Revocar, anular y suspender se distinguen porque: | I117: Revoca el juez, anula la administración y suspende el superior jerárquico | J117: Revoca la administración, anula el juez y suspende quien tenga competencia | K117: Revoca el superior, anula el Ministerio Público y suspende el ordenador | L117: b | M117: La revocatoria directa es una potestad de la administración, la nulidad la declara el juez y la suspensión es una medida temporal que adopta quien tiene competencia para ello. | N117: «Revoca el juez, anula la administración…» y «Revoca el superior, anula el Ministerio…» reparten los tres verbos entre autoridades distintas de las que el ordenamiento habilita para cada actuación. | O117: Ley 1437 de 2011, arts. 93 y ss.; art. 137 | P117: SI | Q117: Alta
A118: F0117 | B118: PS 2782 de 2026 - ESE 2 - HUHMP Neiva | C118: Precision juridica del verbo | D118: Profesional | E118: C039 | F118: Caso 039 | G118: En la revisión de un proyecto de acto administrativo, la asesora observa que el documento usa indistintamente los verbos notificar, comunicar y publicar, y en otro aparte confunde revocar con anular. | H118: Citar y convocar se diferencian en que: | I118: Se cita a un cuerpo colegiado y se convoca a una persona determinada | J118: Se cita a una persona determinada y se convoca a un cuerpo colegiado | K118: Se cita mediante aviso público y se convoca mediante oficio personal | L118: b | M118: La citación se dirige a una persona determinada para una actuación concreta, mientras la convocatoria llama a un colegiado o a un conjunto de destinatarios. | N118: «Se cita a un cuerpo colegiado…» invierte los destinatarios de cada verbo y «Se cita mediante aviso público y…» los distingue por el medio de comunicación, que no es el criterio. | O118: Ley 1437 de 2011; Ley 909 de 2004, art. 31 | P118: SI | Q118: Alta
A119: F0118 | B119: PS 2782 de 2026 - ESE 2 - HUHMP Neiva | C119: Precision juridica del verbo | D119: Técnico | E119: C040 | F119: Caso 040 | G119: En una minuta institucional aparecen las expresiones derogar, modificar y subrogar, y el equipo necesita usarlas correctamente al actualizar un manual. | H119: Derogar una norma significa: | I119: Dejarla sin efectos hacia el futuro por otra norma de igual rango | J119: Dejarla sin efectos por decisión judicial que declara su nulidad | K119: Dejarla sin aplicación temporal mientras se resuelve el fondo | L119: a | M119: La derogación priva de efectos a la norma hacia el futuro y proviene de otra norma de igual o superior jerarquía. | N119: «Dejarla sin efectos por decisión judicial…» corresponde al control judicial y la «Dejarla sin aplicación temporal mientras se…» a una medida temporal que no extingue la norma. | O119: Ley 153 de 1887; C.P. art. 150 | P119: SI | Q119: Alta
A120: F0119 | B120: PS 2782 de 2026 - ESE 2 - HUHMP Neiva | C120: Precision juridica del verbo | D120: Técnico | E120: C040 | F120: Caso 040 | G120: En una minuta institucional aparecen las expresiones derogar, modificar y subrogar, y el equipo necesita usarlas correctamente al actualizar un manual. | H120: Modificar y subrogar se diferencian en que: | I120: Modificar cambia una parte y subrogar sustituye toda la disposición | J120: Modificar sustituye toda la disposición y subrogar cambia una parte | K120: Modificar deroga la disposición y subrogar suspende su aplicación | L120: a | M120: La modificación cambia una parte del texto y la subrogación sustituye integralmente la disposición por una nueva. | N120: «Modificar sustituye toda la disposición y…» invierte el alcance de los dos verbos y «Modificar deroga la disposición y subrogar…» los confunde con la derogatoria y la suspensión. | O120: Ley 153 de 1887 | P120: SI | Q120: Alta
A121: F0120 | B121: PS 2782 de 2026 - ESE 2 - HUHMP Neiva | C121: Precision juridica del verbo | D121: Técnico | E121: C040 | F121: Caso 040 | G121: En una minuta institucional aparecen las expresiones derogar, modificar y subrogar, y el equipo necesita usarlas correctamente al actualizar un manual. | H121: Una norma revocada antes de entrar a producir efectos, como ocurrió con la Resolución 1732 de 2026: | I121: La norma anterior continúa vigente, sin interrupción de su aplicación | J121: La norma anterior queda derogada y el vacío lo llena la costumbre | K121: La norma anterior revive con efectos retroactivos a la derogatoria | L121: a | M121: Al revocarse íntegramente la resolución que derogaba la norma anterior, esta continúa vigente sin interrupción, como ocurrió con la Resolución 3100 de 2019. | N121: «La norma anterior queda derogada y…» y «La norma anterior revive con efectos…» suponen efectos que la revocatoria no produce. | O121: Resolución 2080 de 2026 (Minsalud); Ley 1437 de 2011, art. 93 | P121: SI | Q121: Alta
A122: F0121 | B122: PS 2782 de 2026 - ESE 2 - HUHMP Neiva | C122: Precision juridica del verbo | D122: Profesional | E122: C041 | F122: Caso 041 | G122: Un usuario interpone recurso de reposición contra una decisión del hospital. El jefe jurídico pregunta con qué verbo debe redactarse la parte resolutiva del acto que resuelve el recurso. | H122: Al resolver el recurso, la autoridad puede: | I122: Derogar, subrogar o adicionar la decisión recurrida | J122: Anular, suspender o inaplicar la decisión recurrida | K122: Confirmar, modificar o revocar la decisión recurrida | L122: c | M122: El artículo 80 del CPACA dispone que al decidir los recursos se resuelve sobre las peticiones, confirmando, modificando o revocando la decisión. | N122: «Anular, suspender o inaplicar la decisión…» usa verbos del control judicial y de las medidas cautelares, que no corresponden a la autoridad que resuelve el recurso; «Derogar, subrogar o adicionar la decisión…» usa verbos propios de la técnica normativa aplicable a normas, no a actos administrativos particulares. | O122: Ley 1437 de 2011, art. 80 | P122: SI | Q122: Alta
A123: F0122 | B123: PS 2782 de 2026 - ESE 2 - HUHMP Neiva | C123: Precision juridica del verbo | D123: Profesional | E123: C041 | F123: Caso 041 | G123: Un usuario interpone recurso de reposición contra una decisión del hospital. El jefe jurídico pregunta con qué verbo debe redactarse la parte resolutiva del acto que resuelve el recurso. | H123: Si la decisión recurrida creó una situación jurídica particular y la administración quiere dejarla sin efectos por fuera del recurso, debe: | I123: Anularla por acto motivado y comunicarlo al titular de la situación | J123: Suspenderla y abrir un nuevo estudio del caso por la administración | K123: Revocarla con el consentimiento expreso y escrito del titular | L123: c | M123: La revocatoria directa de actos de contenido particular y concreto exige el consentimiento previo, expreso y escrito del titular, salvo las excepciones legales. | N123: «Anularla por acto motivado y comunicarlo…» atribuye a la administración un verbo que corresponde al juez; «Suspenderla y abrir un nuevo estudio…» usa una medida temporal que no extingue el acto ni sustituye la revocatoria. | O123: Ley 1437 de 2011, arts. 93 y 97 | P123: SI | Q123: Alta
A124: F0123 | B124: PS 2782 de 2026 - ESE 2 - HUHMP Neiva | C124: Precision juridica del verbo | D124: Profesional | E124: C041 | F124: Caso 041 | G124: Un usuario interpone recurso de reposición contra una decisión del hospital. El jefe jurídico pregunta con qué verbo debe redactarse la parte resolutiva del acto que resuelve el recurso. | H124: El ciudadano quiere que un juez deje sin efectos el acto. El verbo técnicamente correcto en su demanda es: | I124: Solicitar que la administración revoque el acto y lo sustituya por otro | J124: Solicitar la nulidad del acto y el restablecimiento del derecho | K124: Solicitar que el superior derogue el acto y expida uno nuevo | L124: b | M124: Ante la jurisdicción se pide la declaratoria de nulidad del acto y el restablecimiento del derecho; la revocatoria es potestad de la administración. | N124: «Solicitar que la administración revoque el…» pide a un juez una actuación administrativa; «Solicitar que el superior derogue el…» emplea un verbo reservado a las normas, no a los actos administrativos. | O124: Ley 1437 de 2011, art. 138 | P124: SI | Q124: Alta
A125: F0124 | B125: PS 2782 de 2026 - ESE 2 - HUHMP Neiva | C125: Precision juridica del verbo | D125: Profesional | E125: C042 | F125: Caso 042 | G125: En el proceso de selección, el equipo de talento humano redacta comunicaciones sobre los resultados y usa indistintamente los verbos inadmitir, excluir y declarar desierto. | H125: Al aspirante que no acredita los requisitos mínimos del empleo se le debe: | I125: Declararlo desierto, por no proveerse el empleo ofertado | J125: Excluirlo, por incurrir en una causal prevista en el acuerdo | K125: Inadmitirlo, por no acreditar los requisitos mínimos del empleo | L125: c | M125: En la Verificación de Requisitos Mínimos el aspirante que no acredita los requisitos resulta inadmitido y no continúa en el proceso. | N125: «Excluirlo, por incurrir en una causal…» corresponde a quien incurre en causales como el fraude o la suplantación; «Declararlo desierto, por no proveerse el…» se predica del empleo sin inscritos, no del aspirante. | O125: Acuerdo CNSC N° 36 de 2026, art. 13; Anexo Técnico E.S.E. 2 | P125: SI | Q125: Basica
A126: F0125 | B126: PS 2782 de 2026 - ESE 2 - HUHMP Neiva | C126: Precision juridica del verbo | D126: Profesional | E126: C042 | F126: Caso 042 | G126: En el proceso de selección, el equipo de talento humano redacta comunicaciones sobre los resultados y usa indistintamente los verbos inadmitir, excluir y declarar desierto. | H126: Al aspirante que aporta un documento falso se le debe: | I126: Inadmitirlo en la verificación de requisitos mínimos del empleo | J126: Excluirlo en cualquier momento en que se compruebe el hecho | K126: Retirarlo de la lista de elegibles una vez esta se conforme | L126: b | M126: Aportar documentos falsos o adulterados es causal de exclusión, aplicable en cualquier etapa del proceso en que se compruebe. | N126: «Inadmitirlo en la verificación de requisitos…» usa el verbo de la VRM para una conducta sancionable; «Retirarlo de la lista de elegibles…» limita el efecto a una etapa final cuando la causal opera en cualquier momento. | O126: Acuerdo CNSC N° 36 de 2026, art. 7 | P126: SI | Q126: Basica
A127: F0126 | B127: PS 2782 de 2026 - ESE 2 - HUHMP Neiva | C127: Precision juridica del verbo | D127: Profesional | E127: C042 | F127: Caso 042 | G127: En el proceso de selección, el equipo de talento humano redacta comunicaciones sobre los resultados y usa indistintamente los verbos inadmitir, excluir y declarar desierto. | H127: Cuando un empleo ofertado en ascenso no registra inscritos, la CNSC debe: | I127: Excluir el empleo de la oferta pública de empleos de carrera | J127: Declararlo desierto y proveerlo en la modalidad de abierto | K127: Inadmitir el empleo y trasladarlo al siguiente proceso | L127: b | M127: Las vacantes de ascenso sin inscritos se declaran desiertas y se proveen mediante el mismo proceso en la modalidad abierto. | N127: «Excluir el empleo de la oferta…» y «Inadmitir el empleo y trasladarlo al…» aplican a aspirantes, no a vacantes: el verbo cambia según recaiga sobre la persona o sobre el empleo. | O127: Ley 1960 de 2019, art. 2; Acuerdo CNSC N° 36 de 2026, art. 3 | P127: SI | Q127: Basica
... A157: F0156 | B157: PS 2782 de 2026 - ESE 2 - HUHMP Neiva | C157: Precision juridica del verbo | D157: Técnico | E157: C052 | F157: Caso 052 | G157: Un auditor sanitario visita el hospital y debe describir correctamente las medidas que puede adoptar la autoridad. | H157: Terminado el procedimiento administrativo sancionatorio, la autoridad puede: | I157: Adoptar una medida sanitaria de seguridad como sanción | J157: Imponer la sanción mediante acto motivado | K157: Suspender el procedimiento | L157: b | M157: La sanción se impone mediante acto administrativo motivado al término del procedimiento sancionatorio. | N157: «Adoptar una medida sanitaria de seguridad…» usa como sanción una medida preventiva; «Suspender el procedimiento» describe una decisión procesal, no el resultado del procedimiento. | O157: Ley 1437 de 2011, arts. 47 a 50 | P157: SI | Q157: Alta
A158: F0157 | B158: PS 2782 de 2026 - ESE 2 - HUHMP Neiva | C158: Sistema de salud y Ley 100 de 1993 | D158: Profesional | E158: C053 | F158: Caso 053 | G158: La oficina de planeación revisa cómo se financia la operación del hospital y cuál es el papel de cada actor del sistema. | H158: La UPC es: | I158: El valor anual que reconoce el sistema por cada afiliado para financiar el plan de beneficios | J158: La tarifa que cobra la IPS por cada atención | K158: El copago que paga el usuario | L158: a | M158: La Unidad de Pago por Capitación es el valor anual reconocido por afiliado para financiar el plan de beneficios. | N158: «La tarifa que cobra la IPS…» describe la tarifa contractual del prestador y «El copago que paga el usuario» un pago moderador a cargo del usuario. | O158: Ley 100 de 1993, art. 182 | P158: SI | Q158: Basica | R158: repaso
A159: F0158 | B159: PS 2782 de 2026 - ESE 2 - HUHMP Neiva | C159: Sistema de salud y Ley 100 de 1993 | D159: Profesional | E159: C053 | F159: Caso 053 | G159: La oficina de planeación revisa cómo se financia la operación del hospital y cuál es el papel de cada actor del sistema. | H159: La ADRES cumple la función de: | I159: Administrar los recursos del sistema general de seguridad social en salud | J159: Habilitar los servicios de salud | K159: Vigilar a los prestadores | L159: a | M159: La ADRES administra los recursos del sistema y realiza los reconocimientos y giros que le competen. | N159: «Habilitar los servicios de salud» corresponde a las entidades territoriales y «Vigilar a los prestadores» a la Superintendencia Nacional de Salud. | O159: Ley 1753 de 2015, art. 66 | P159: SI | Q159: Basica | R159: repaso
A160: F0159 | B160: PS 2782 de 2026 - ESE 2 - HUHMP Neiva | C160: Sistema de salud y Ley 100 de 1993 | D160: Profesional | E160: C053 | F160: Caso 053 | G160: La oficina de planeación revisa cómo se financia la operación del hospital y cuál es el papel de cada actor del sistema. | H160: La afiliación al sistema es: | I160: Optativa si la persona tiene medicina prepagada | J160: Voluntaria para trabajadores independientes | K160: Obligatoria para todos los residentes en Colombia | L160: c | M160: La afiliación al SGSSS es obligatoria para todos los residentes en el país. | N160: «Voluntaria para trabajadores independientes» y «Optativa si la persona tiene medicina…» crean excepciones que la ley no contempla; la prepagada es complementaria, no sustituye la afiliación. | O160: Ley 100 de 1993, art. 153 | P160: SI | Q160: Basica | R160: repaso
A161: F0160 | B161: PS 2782 de 2026 - ESE 2 - HUHMP Neiva | C161: Sistema de salud y Ley 100 de 1993 | D161: Profesional | E161: C054 | F161: Caso 054 | G161: El comité financiero analiza la relación contractual entre el hospital y las EPS. | H161: El acuerdo de voluntades entre EPS e IPS debe contener como mínimo: | I161: Solo el valor total del contrato | J161: Objeto, población, servicios, tarifas, mecanismos de pago y vigencia | K161: Solo las tarifas de los procedimientos | L161: b | M161: Los acuerdos de voluntades deben precisar objeto, población, servicios contratados, tarifas, mecanismo de pago y vigencia. | N161: «Solo el valor total del contrato» y «Solo las tarifas de los procedimientos» omiten elementos esenciales sin los cuales el acuerdo es indeterminado. | O161: Decreto 780 de 2016, (Decreto Único Reglamentario del Sector Salud); Resolución 3047 de 2008 | P161: SI | Q161: Basica | R161: repaso
A162: F0161 | B162: PS 2782 de 2026 - ESE 2 - HUHMP Neiva | C162: Sistema de salud y Ley 100 de 1993 | D162: Profesional | E162: C054 | F162: Caso 054 | G162: El comité financiero analiza la relación contractual entre el hospital y las EPS. | H162: El mecanismo de pago por capitación implica que: | I162: El prestador recibe un valor fijo por persona y período, asumiendo el riesgo de la demanda | J162: Se paga cada actividad realizada | K162: Se paga por caso o conjunto de atenciones | L162: a | M162: En la capitación se paga un valor fijo por persona y período, trasladando parte del riesgo al prestador. | N162: «Se paga cada actividad realizada» describe el pago por evento y «Se paga por caso o conjunto…» el pago global prospectivo o por paquete. | O162: Decreto 780 de 2016, (Decreto Único Reglamentario del Sector Salud) | P162: SI | Q162: Basica | R162: repaso
A163: F0162 | B163: PS 2782 de 2026 - ESE 2 - HUHMP Neiva | C163: Sistema de salud y Ley 100 de 1993 | D163: Profesional | E163: C054 | F163: Caso 054 | G163: El comité financiero analiza la relación contractual entre el hospital y las EPS. | H163: La auditoría de cuentas médicas tiene por objeto: | I163: Fijar las tarifas del contrato | J163: Verificar la pertinencia, la calidad y el soporte de los servicios facturados | K163: Sustituir la historia clínica | L163: b | M163: La auditoría verifica pertinencia, calidad y soportes de lo facturado frente a lo pactado. | N163: «Fijar las tarifas del contrato» es materia de negociación contractual y «Sustituir la historia clínica» confunde auditoría con registro clínico. | O163: Decreto 780 de 2016, (Decreto Único Reglamentario del Sector Salud) | P163: SI | Q163: Basica | R163: repaso
A164: F0163 | B164: PS 2782 de 2026 - ESE 2 - HUHMP Neiva | C164: Sistema de salud y Ley 100 de 1993 | D164: Técnico | E164: C055 | F164: Caso 055 | G164: Un técnico de admisiones debe explicar el plan de beneficios y las exclusiones a un usuario. | H164: El plan de beneficios en salud con cargo a la UPC: | I164: Cubre lo necesario para la promoción, prevención, diagnóstico, tratamiento y rehabilitación, salvo exclusiones expresas | J164: Cubre solo urgencias | K164: Cubre solo lo que autorice la EPS | L164: a | M164: El plan de beneficios cubre de manera integral los servicios necesarios, salvo lo expresamente excluido. | N164: «Cubre solo urgencias» y «Cubre solo lo que autorice la…» reducen la cobertura legal a una franja mínima o a la voluntad del asegurador. | O164: Ley 1751 de 2015, art. 15; Resolución de PBS vigente | P164: SI | Q164: Basica | R164: repaso
A165: F0164 | B165: PS 2782 de 2026 - ESE 2 - HUHMP Neiva | C165: Sistema de salud y Ley 100 de 1993 | D165: Técnico | E165: C055 | F165: Caso 055 | G165: Un técnico de admisiones debe explicar el plan de beneficios y las exclusiones a un usuario. | H165: Los servicios no financiados con la UPC: | I165: Se gestionan por el mecanismo de prescripción vigente (MIPRES) y su financiación tiene reglas propias | J165: No pueden prestarse | K165: Los paga siempre el usuario | L165: a | M165: Los servicios no financiados con la UPC se prescriben por la herramienta dispuesta para ello y su financiación sigue reglas específicas. | N165: «No pueden prestarse» niega el acceso y «Los paga siempre el usuario» traslada al usuario un costo que la normativa no le asigna. | O165: Decreto 780 de 2016, (Decreto Único Reglamentario del Sector Salud); Resolución 1885 de 2018 | P165: SI | Q165: Basica | R165: repaso
A166: F0165 | B166: PS 2782 de 2026 - ESE 2 - HUHMP Neiva | C166: Sistema de salud y Ley 100 de 1993 | D166: Técnico | E166: C055 | F166: Caso 055 | G166: Un técnico de admisiones debe explicar el plan de beneficios y las exclusiones a un usuario. | H166: La portabilidad permite al afiliado: | I166: Recibir atención en un municipio distinto al de afiliación | J166: Cambiar de EPS cuando quiera sin requisitos | K166: Elegir el prestador que desee a nivel nacional sin restricción | L166: a | M166: La portabilidad garantiza el acceso a los servicios en un municipio distinto al de afiliación. | N166: «Cambiar de EPS cuando quiera sin…» describe el traslado, con reglas de permanencia; «Elegir el prestador que desee a…» excede el derecho de elección dentro de la red. | O166: Decreto 780 de 2016, (Decreto Único Reglamentario del Sector Salud) | P166: SI | Q166: Basica | R166: repaso
A167: F0166 | B167: PS 2782 de 2026 - ESE 2 - HUHMP Neiva | C167: Sistema de salud y Ley 100 de 1993 | D167: Profesional | E167: C056 | F167: Caso 056 | G167: La gerencia evalúa el desempeño de la red pública del departamento. | H167: La rectoría del sistema de salud en el departamento corresponde a: | I167: A la EPS con mayor número de afiliados | J167: La secretaría departamental de salud, en el marco de sus competencias | K167: Al hospital de mayor complejidad | L167: b | M167: La dirección del sector salud en el departamento corresponde a la entidad territorial, conforme a la Ley 715 de 2001. | N167: «A la EPS con mayor número…» y «Al hospital de mayor complejidad» son actores del sistema sin competencia de rectoría territorial. | O167: Ley 715 de 2001, art. 43 | P167: SI | Q167: Basica | R167: repaso
A168: F0167 | B168: PS 2782 de 2026 - ESE 2 - HUHMP Neiva | C168: Sistema de salud y Ley 100 de 1993 | D168: Profesional | E168: C056 | F168: Caso 056 | G168: La gerencia evalúa el desempeño de la red pública del departamento. | H168: La inspección, vigilancia y control del sistema corresponde principalmente a: | I168: La Procuraduría General | J168: La Contraloría General | K168: La Superintendencia Nacional de Salud | L168: c | M168: La Superintendencia Nacional de Salud ejerce la inspección, vigilancia y control sobre los actores del sistema. | N168: «La Contraloría General» ejerce control fiscal y «La Procuraduría General» control disciplinario: ninguno reemplaza la vigilancia sectorial. | O168: Ley 1122 de 2007, art. 35 | P168: SI | Q168: Basica | R168: repaso
A169: F0168 | B169: PS 2782 de 2026 - ESE 2 - HUHMP Neiva | C169: Sistema de salud y Ley 100 de 1993 | D169: Profesional | E169: C056 | F169: Caso 056 | G169: La gerencia evalúa el desempeño de la red pública del departamento. | H169: El hospital de alta complejidad dentro de la red debe: | I169: Rechazar toda remisión de primer nivel | J169: Atender toda consulta que llegue, sea cual sea su complejidad | K169: Atender lo que corresponde a su nivel y devolver al nivel resolutivo lo que no lo requiere | L169: c | M169: La organización en red implica resolver en el nivel que corresponde y contrarreferir lo que puede atenderse en menor complejidad. | N169: «Atender toda consulta que llegue, sea…» satura la alta complejidad y «Rechazar toda remisión de primer nivel» desconoce la obligación de recibir lo pertinente. | O169: Ley 1438 de 2011; Decreto 780 de 2016, (Decreto Único Reglamentario del Sector Salud) | P169: SI | Q169: Basica | R169: repaso
... A334: F0333 | B334: PS 2782 de 2026 - ESE 2 - HUHMP Neiva | C334: Regimen disciplinario y CPACA | D334: Profesional | E334: C111 | F334: Caso 111 | G334: Un servidor pregunta por el régimen de sus deberes y prohibiciones. | H334: La sanción de destitución e inhabilidad general se impone por: | I334: Faltas leves reiteradas | J334: Cualquier falta grave | K334: Faltas gravísimas dolosas o realizadas con culpa gravísima | L334: c | M334: La destitución e inhabilidad general corresponde a faltas gravísimas dolosas o con culpa gravísima. | N334: «Cualquier falta grave» y «Faltas leves reiteradas» aplican una sanción desproporcionada a la calificación de la falta. | O334: Ley 1952 de 2019, art. 48 | P334: SI | Q334: Basica | R334: repaso
A335: F0334 | B335: PS 2782 de 2026 - ESE 2 - HUHMP Neiva | C335: Precision juridica del verbo | D335: Profesional | E335: C112 | F335: Caso 112 | G335: En una minuta se usan indistintamente los verbos de la ejecución del acto. | H335: Cuando la administración lleva a la práctica su propia decisión ejecutoriada, el verbo es: | I335: Ejecutoriar el acto | J335: Ejecutar el acto | K335: Ejecutarse de plano | L335: b | M335: La administración ejecuta el acto en firme; la ejecutoria es la condición que lo habilita. | N335: «Ejecutoriar el acto» nombra la condición, no la acción; «Ejecutarse de plano» no describe la actuación. | O335: Ley 1437 de 2011, art. 89 | P335: SI | Q335: Alta
...

Sheet Comportamentales
A1: id | B1: competencia | C1: situacion | D1: a | E1: b | F1: c | G1: puntos_a | H1: puntos_b | I1: puntos_c | J1: activa | K1: tipo_v2 | L1: consigna | M1: invertida
A2: B0001 | B2: Orientación al usuario y al ciudadano | C2: Un usuario llega alterado porque le reprogramaron la cita por tercera vez. El agendamiento no depende de usted. | D2: Escucha, verifica en el sistema, explica la causa y gestiona con el área responsable una fecha concreta | E2: Le ofrece disculpas y le sugiere volver cuando haya menos gente | F2: Le explica que el trámite no depende de su área y le indica dónde reclamar | G2: 3 | H2: 1 | I2: 2 | J2: NO | L2: ¿Qué hace usted? | M2: NO
A3: B0002 | B3: Orientación al usuario y al ciudadano | C3: Una persona mayor no entiende el formato de consentimiento que debe firmar antes de un procedimiento. | D3: Pide al acompañante que firme para agilizar | E3: Le entrega el formato y le pide que lo lea con calma en la sala | F3: Explica en lenguaje sencillo, verifica que comprendió y solo entonces solicita la firma | G3: 1 | H3: 2 | I3: 3 | J3: NO | L3: ¿Qué hace usted? | M3: NO
A4: B0003 | B4: Orientación a resultados | C4: Un reporte obligatorio vence mañana y falta información de otra dependencia. | D4: Solicita por escrito lo que falta, informa el riesgo a su jefe y avanza con lo disponible | E4: Reporta datos estimados para cumplir el plazo | F4: Espera la información hasta el último momento y decide entonces | G4: 3 | H4: 1 | I4: 2 | J4: NO | L4: ¿Qué hace usted? | M4: NO
A5: B0004 | B5: Orientación a resultados | C5: Le asignan tres tareas urgentes el mismo día y no alcanza a hacerlas todas. | D5: Empieza por la más fácil para mostrar avance | E5: Prioriza según impacto y plazo, acuerda con su jefe el orden y comunica los tiempos | F5: Intenta las tres a la vez y entrega lo que alcance | G5: 2 | H5: 3 | I5: 1 | J5: NO | L5: ¿Qué hace usted? | M5: NO
A6: B0005 | B6: Transparencia | C6: Un proveedor con el que usted tramita un contrato le ofrece un obsequio de bajo valor. | D6: Lo rechaza verbalmente y no informa a nadie | E6: Lo acepta porque su valor es bajo y lo destina al fondo de empleados | F6: Rechaza el obsequio y deja constancia escrita del ofrecimiento ante su jefe inmediato | G6: 2 | H6: 1 | I6: 3 | J6: NO | L6: ¿Qué hace usted? | M6: NO
A7: B0006 | B7: Transparencia | C7: Un familiar suyo se presenta a un proceso contractual en el que usted participa. | D7: Continúa participando pero avisa verbalmente a un compañero | E7: Manifiesta el impedimento por escrito y se aparta del trámite | F7: Continúa porque confía en su imparcialidad | G7: 2 | H7: 3 | I7: 1 | J7: NO | L7: ¿Qué hace usted? | M7: NO
A8: B0007 | B8: Compromiso con la organización | C8: Detecta un error propio en un informe que ya llegó a la gerencia. | D8: Corrige el archivo compartido y espera a que alguien pregunte | E8: Guarda silencio porque el error es menor | F8: Informa de inmediato el error, remite la versión corregida y explica su impacto | G8: 2 | H8: 1 | I8: 3 | J8: NO | L8: ¿Qué hace usted? | M8: NO
A9: B0008 | B9: Compromiso con la organización | C9: Un compañero critica en público a la entidad frente a usuarios en la sala de espera. | D9: Cambia de tema y sigue con su trabajo | E9: Le propone en privado llevar el asunto a los canales internos y atiende a los usuarios | F9: Se suma a la crítica para no quedar mal con el compañero | G9: 2 | H9: 3 | I9: 1 | J9: NO | L9: ¿Qué hace usted? | M9: NO
A10: B0009 | B10: Trabajo en equipo | C10: Un compañero se retrasa por sobrecarga y la entrega del equipo está en riesgo. | D10: Propone al líder redistribuir tareas y apoya en lo que puede sin descuidar lo suyo | E10: Asume todo el trabajo del compañero sin informar a nadie | F10: Entrega su parte y deja constancia de que el retraso no es suyo | G10: 3 | H10: 1 | I10: 2 | J10: NO | L10: ¿Qué hace usted? | M10: NO
A11: B0010 | B11: Trabajo en equipo | C11: En una reunión, su propuesta es descartada por el grupo con argumentos técnicos. | D11: Acepta en silencio y se desentiende de la ejecución | E11: Insiste en su propuesta por fuera de la reunión | F11: Acoge la decisión, aporta a la alternativa elegida y deja registrada su observación | G11: 2 | H11: 1 | I11: 3 | J11: NO | L11: ¿Qué hace usted? | M11: NO
A12: B0011 | B12: Adaptación al cambio | C12: El hospital implementa un módulo nuevo del sistema de información y cambia su proceso. | D12: Participa en la capacitación, ajusta su proceso y reporta las dificultades que encuentra | E12: Mantiene el registro paralelo en papel para no cambiar | F12: Usa el módulo solo cuando es indispensable | G12: 3 | H12: 1 | I12: 2 | J12: NO | L12: ¿Qué hace usted? | M12: NO
A13: B0012 | B13: Adaptación al cambio | C13: Lo trasladan temporalmente a un servicio que no conoce. | D13: Manifiesta que no es su área y limita su aporte | E13: Espera a que el jefe del servicio le asigne tareas simples | F13: Solicita inducción, identifica los procedimientos críticos y pide retroalimentación | G13: 1 | H13: 2 | I13: 3 | J13: NO | L13: ¿Qué hace usted? | M13: NO
... A31: B0030 | B31: Gestión de procedimientos | C31: Un usuario le pide saltarse un paso del procedimiento por urgencia. | D31: Explica por qué existe el paso y busca la ruta prevista para casos urgentes | E31: Se lo salta por esta vez | F31: Le dice que no hay nada que hacer | G31: 3 | H31: 2 | I31: 1 | J31: NO | L31: ¿Qué hace usted? | M31: NO
A32: B0031 | B32: Orientación al usuario y al ciudadano | C32: Son las 11:40 y usted atiende el último turno antes del almuerzo. Llega una señora de otro municipio que viajó dos horas y trae la documentación incompleta: le falta un soporte que puede pedir por correo, pero tardaría dos días. Detrás hay cuatro personas esperando y su jefe insiste en cumplir el indicador de tiempo de atención. | D32: Le explica que sin el soporte no puede radicar y le entrega por escrito la lista de lo que debe traer | E32: Le recibe todo sin revisar para no demorar la fila y le dice que después la llaman si algo falta | F32: Recibe lo que trae, le indica con precisión cómo enviar el soporte faltante y le deja el trámite radicado | G32: 2 | H32: 1 | I32: 3 | J32: SI | K32: v2 | L32: ¿Qué hace usted? | M32: NO
A33: B0032 | B33: Orientación al usuario y al ciudadano | C33: Un usuario lleva veinte minutos discutiendo en voz alta porque su cita fue reprogramada. La programación no depende de usted y la sala está llena de gente esperando. Su compañera le sugiere que lo ignore hasta que se canse y el vigilante pregunta si lo retira del lugar. | D33: Escucha su reclamo en la ventanilla, le pide calma y le entrega el formato para presentar la queja formal | E33: Le explica que la programación no es su área y le indica en qué oficina puede reclamar por ese asunto | F33: Lo atiende en un espacio aparte, verifica su caso en el sistema y le da una respuesta con fecha concreta | G33: 2 | H33: 1 | I33: 3 | J33: SI | K33: v2 | L33: ¿Qué hace usted? | M33: NO
A34: B0033 | B34: Orientación a resultados | C34: El informe mensual vence mañana y falta un dato que depende de otra dependencia que no responde hace tres días. Su jefe está de comisión y no contesta. Entregar incompleto afecta el indicador del área; entregar tarde también, y ambos quedan registrados en el sistema de seguimiento. | D34: Reitera la solicitud por escrito, informa el riesgo al superior encargado y entrega con el dato pendiente identificado | E34: Entrega el informe con el dato en blanco y una nota que identifica cuál dependencia no lo remitió a tiempo | F34: Estima el dato con el promedio de los meses anteriores para poder entregar el informe completo a tiempo | G34: 3 | H34: 2 | I34: 1 | J34: SI | K34: v2 | L34: ¿Qué hace usted? | M34: NO
A35: B0034 | B35: Orientación a resultados | C35: Le asignan tres tareas para el mismo viernes: un reporte a un ente de control, una presentación para la junta directiva y la revisión de un procedimiento interno. Ninguna puede aplazarse sin costo, y su jefe le dice que las tres son prioritarias y que se organice como pueda. | D35: Trabaja en las tres de manera simultánea y entrega el viernes lo que haya logrado adelantar de cada una | E35: Empieza por la del ente de control, que tiene consecuencias legales, y avanza con las otras según alcance | F35: Estima el tiempo de cada una, propone al jefe un orden con fechas | G35: 1 | H35: 2 | I35: 3 | J35: SI | K35: v2 | L35: ¿Qué hace usted? | M35: NO
A36: B0035 | B36: Transparencia | C36: Un proveedor con el que usted tramita un contrato le envía por la fiesta de fin de año una canasta navideña a su casa, sin remitente visible. Usted la recibe sin saber de quién era y al día siguiente él se lo comenta entre risas en una llamada de trabajo. | D36: Conserva la canasta porque ya fue recibida y decide no volver a tratar temas personales con ese proveedor | E36: Devuelve la canasta al proveedor, le pide que no se repita y no informa el hecho dentro de la entidad | F36: Devuelve la canasta, deja constancia escrita del hecho ante su jefe y continúa el trámite con normalidad | G36: 1 | H36: 2 | I36: 3 | J36: SI | K36: v2 | L36: ¿Qué hace usted? | M36: NO
A37: B0036 | B37: Transparencia | C37: Su cuñado se presenta a una convocatoria de prestación de servicios en la que usted revisa las hojas de vida. Es el candidato con mejor perfil y la entidad necesita cubrir el cargo esta semana. Nadie en la oficina conoce el parentesco y su jefe le pide agilizar la evaluación. | D37: Declara el impedimento por escrito, se aparta de la evaluación y propone quién puede asumirla esta semana | E37: Le comenta el parentesco a su jefe de manera verbal y continúa la evaluación aplicando criterios objetivos | F37: Evalúa las hojas de vida y deja que sea el jefe quien tome la decisión final sobre la contratación | G37: 3 | H37: 2 | I37: 1 | J37: SI | K37: v2 | L37: ¿Qué hace usted? | M37: NO
A38: B0037 | B38: Compromiso con la organización | C38: Detecta que un informe suyo, ya enviado a la gerencia y citado en una reunión con el ente de control, tiene un error de cálculo que cambia una cifra en un ocho por ciento. Nadie lo ha notado. Corregirlo implica reconocer el error frente a quienes ya usaron el dato. | D38: Informa el error de inmediato, remite la versión corregida y precisa qué decisiones pudo haber afectado | E38: Deja el dato como está y ajusta los informes siguientes para que la serie quede consistente hacia adelante | F38: Corrige el archivo, lo reenvía con el asunto actualizado y espera a que alguien pregunte por la diferencia | G38: 3 | H38: 1 | I38: 2 | J38: SI | K38: v2 | L38: ¿Qué hace usted? | M38: NO
A39: B0038 | B39: Compromiso con la organización | C39: En una reunión con usuarios, un compañero critica en voz alta la gestión de la entidad y afirma que los procesos no sirven. Varios asistentes asienten. Usted comparte parte del diagnóstico, pero no la forma ni el lugar, y el compañero es más antiguo que usted en la institución. | D39: Guarda silencio en la reunión y después lleva el tema al comité interno donde corresponde tratarlo | E39: Reencauza la reunión hacia lo que sí puede resolverse y luego habla en privado con el compañero | F39: Aclara en el momento que esa es una opinión personal suya y continúa con el orden del día previsto | G39: 2 | H39: 3 | I39: 1 | J39: SI | K39: v2 | L39: ¿Qué hace usted? | M39: NO
A40: B0039 | B40: Trabajo en equipo | C40: Un compañero de su equipo está atrasado porque asumió el trabajo de otra persona que salió a incapacidad. La entrega conjunta es en dos días. Si usted lo apoya, descuida una tarea propia que también vence, y el líder del equipo aún no se ha enterado de la situación. | D40: Informa al líder el riesgo real, propone una redistribución con plazos y apoya en lo que pueda sostener | E40: Entrega su parte a tiempo y aclara por correo que el retraso del equipo no corresponde a su actividad | F40: Le ayuda con lo más urgente en horas adicionales y comenta la situación al líder cuando se entregue todo | G40: 3 | H40: 1 | I40: 2 | J40: SI | K40: v2 | L40: ¿Qué hace usted? | M40: NO
A41: B0040 | B41: Trabajo en equipo | C41: Otra área comete un error que afecta su proceso y usted debe rehacer el trabajo de dos días. El responsable es una persona con la que ya ha tenido roces. Su jefe le pregunta qué pasó delante de todo el equipo en la reunión de seguimiento semanal. | D41: Describe el hecho con datos, sin señalar personas, y propone un ajuste conjunto entre las dos áreas | E41: Explica que el error vino de la otra área y aclara que ya lo está corrigiendo por su cuenta | F41: Responde que hubo un inconveniente menor y habla luego del tema directamente con el responsable | G41: 3 | H41: 2 | I41: 1 | J41: SI | K41: v2 | L41: ¿Qué hace usted? | M41: NO
A42: B0041 | B42: Adaptación al cambio | C42: La entidad cambia el aplicativo con el que usted trabaja hace seis años. La nueva versión es más lenta en su tarea principal, aunque mejora el reporte global. Varios compañeros siguen usando el archivo antiguo en paralelo y el jefe no ha dicho nada al respecto. | D42: Adopta el aplicativo nuevo y resuelve como puede la demora, sin reportar la dificultad que encontró | E42: Mantiene el archivo antiguo para su tarea y usa el aplicativo solo cuando debe generar el reporte global | F42: Usa el aplicativo nuevo, documenta con datos dónde se pierde tiempo y lleva la observación al responsable | G42: 2 | H42: 1 | I42: 3 | J42: SI | K42: v2 | L42: ¿Qué hace usted? | M42: NO
A43: B0042 | B43: Adaptación al cambio | C43: Lo trasladan por tres meses a un servicio que no conoce, con procedimientos distintos y un equipo que ya tiene su ritmo. El jefe del servicio está ocupado y le dice que aprenda observando. La primera semana le asignan tareas para las que no tiene claridad. | D43: Observa una semana, toma notas y empieza a trabajar preguntando cuando encuentra algo que no comprende | E43: Solicita una inducción breve, identifica los procedimientos críticos y confirma cada duda antes de actuar | F43: Ejecuta las tareas asignadas replicando lo que ve hacer a los compañeros más antiguos del servicio | G43: 2 | H43: 3 | I43: 1 | J43: SI | K43: v2 | L43: ¿Qué hace usted? | M43: NO
... A169: B0168 | B169: Trabajo en equipo | C169: En la entrega del turno del puesto de control del aeropuerto, quien sale omite decir que un cargamento quedó pendiente de verificación. Usted lo descubre dos horas después revisando el registro. Es la tercera vez este mes que la entrega llega incompleta | D169: Registrar el hallazgo y comentarlo en la reunión mensual del grupo | E169: Hablar con esa persona y acordar una lista corta de puntos obligatorios | F169: Informar el hecho al coordinador para que él corrija al responsable | G169: 2 | H169: 3 | I169: 1 | J169: SI | K169: v3 | L169: ¿Cuál es la conducta más efectiva? | M169: NO

Sheet Resumen
A1: Solaris Merit Neiva - Resumen del banco
A3: Concurso | B3: PS 2782 de 2026 - ESE 2 - HUHMP Neiva
A4: Preguntas funcionales | B4: =COUNTA(Funcionales!A2:A2000) -> 917
A5: Casos funcionales | B5: =SUMPRODUCT((Funcionales!E2:E2000<>"")/COUNTIF(Funcionales!E2:E2000,Funcionales!E2:E2000&"")) -> 311
A6: Preguntas comportamentales | B6: =COUNTA(Comportamentales!A2:A500) -> 168
A7: Total preguntas | B7: =B4+B6 -> 1085
A9: Preguntas por eje
A10: Eje | B10: Preguntas | C10: Casos
A11: Sistema de salud y Ley 100 de 1993 | B11: =COUNTIF(Funcionales!$C$2:$C$2000,$A11) -> 67 | C11: =COUNTIF(Funcionales!$C$2:$C$2000,$A11)/3 -> 22.333333
A12: Ley 1751 de 2015 - derecho fundamental a la salud | B12: =COUNTIF(Funcionales!$C$2:$C$2000,$A12) -> 63 | C12: =COUNTIF(Funcionales!$C$2:$C$2000,$A12)/3 -> 21
A13: Habilitacion y calidad (Resolucion 3100 de 2019) | B13: =COUNTIF(Funcionales!$C$2:$C$2000,$A13) -> 60 | C13: =COUNTIF(Funcionales!$C$2:$C$2000,$A13)/3 -> 20
A14: Seguridad del paciente | B14: =COUNTIF(Funcionales!$C$2:$C$2000,$A14) -> 66 | C14: =COUNTIF(Funcionales!$C$2:$C$2000,$A14)/3 -> 22
A15: Historia clinica y proteccion de datos (Ley 1581 de 2012) | B15: =COUNTIF(Funcionales!$C$2:$C$2000,$A15) -> 63 | C15: =COUNTIF(Funcionales!$C$2:$C$2000,$A15)/3 -> 21
A16: Humanizacion y derechos del paciente | B16: =COUNTIF(Funcionales!$C$2:$C$2000,$A16) -> 54 | C16: =COUNTIF(Funcionales!$C$2:$C$2000,$A16)/3 -> 18
A17: Referencia y contrarreferencia | B17: =COUNTIF(Funcionales!$C$2:$C$2000,$A17) -> 51 | C17: =COUNTIF(Funcionales!$C$2:$C$2000,$A17)/3 -> 17
A18: Urgencias | B18: =COUNTIF(Funcionales!$C$2:$C$2000,$A18) -> 51 | C18: =COUNTIF(Funcionales!$C$2:$C$2000,$A18)/3 -> 17
A19: Gestion hospitalaria y organizacion de la E.S.E. | B19: =COUNTIF(Funcionales!$C$2:$C$2000,$A19) -> 87 | C19: =COUNTIF(Funcionales!$C$2:$C$2000,$A19)/3 -> 29
A20: Contratacion en la E.S.E. y transparencia | B20: =COUNTIF(Funcionales!$C$2:$C$2000,$A20) -> 54 | C20: =COUNTIF(Funcionales!$C$2:$C$2000,$A20)/3 -> 18
A21: Regimen disciplinario y CPACA | B21: =COUNTIF(Funcionales!$C$2:$C$2000,$A21) -> 103 | C21: =COUNTIF(Funcionales!$C$2:$C$2000,$A21)/3 -> 34.333333
A22: Precision juridica del verbo | B22: =COUNTIF(Funcionales!$C$2:$C$2000,$A22) -> 97 | C22: =COUNTIF(Funcionales!$C$2:$C$2000,$A22)/3 -> 32.333333
A23: TOTAL | B23: =SUM(B11:B22) -> 816 | C23: =SUM(C11:C22) -> 272

Sheet Instrucciones
A1: Solaris Merit Neiva - Banco de preguntas de práctica
A3: Concurso: Proceso de Selección No. 2782 de 2026 - Empresas Sociales del Estado 2
A4: Entidad: E.S.E. Hospital Universitario Hernando Moncaleano Perdomo (Neiva, Huila)
A5: Acuerdo de convocatoria: Acuerdo CNSC N° 36 del 9 de abril de 2026 - Anexo Técnico E.S.E. 2 Orden Territorial
A6: Niveles cubiertos: Profesional y Técnico
A8: AVISO IMPORTANTE
A9: Estas preguntas son de PRÁCTICA y fueron elaboradas a partir de la normativa pública citada en cada fila.
A10: NO son preguntas reales de una prueba de la CNSC: las pruebas tienen carácter reservado (Ley 909 de 2004, art. 31 num. 3).
A11: Este material no está afiliado, avalado ni patrocinado por la CNSC ni por la E.S.E. Hospital Universitario Hernando Moncaleano Perdomo.
A13: CÓMO EDITAR ESTE ARCHIVO
A14: 1. Hoja Funcionales: una fila por pregunta. Tres filas con el mismo caso_id comparten el mismo texto_caso (formato de caso con tres enunciados).
A15: 2. Columna respuesta: escriba únicamente a, b o c en minúscula.
... A49: 5. Si no se conoce el artículo con certeza, se deja la norma con su año y no se inventa el artículo.

Sheet Basicas
A1: id | B1: bloque | C1: componente | D1: dificultad | E1: caso | F1: estimulo | G1: enunciado | H1: a | I1: b | J1: c | K1: respuesta | L1: explicacion | M1: porque_no | N1: fuente | O1: activa | P1: ambito | Q1: en_banco_funcional
A2: CB001 | B2: Aptitudes | C2: Lectura crítica | D2: Alta | F2: La entidad publicó que el tiempo promedio de respuesta a las peticiones bajó de 12 a 8 días en el último semestre. El informe aclara que el promedio se calculó sobre las peticiones cerradas en el periodo y que 1.400 peticiones seguían abiertas al corte, algunas radicadas hace más de cuatro meses. | G2: El dato del promedio, tal como está calculado: | H2: Sobrestima la demora real, porque incluye peticiones de semestres anteriores | I2: Refleja la demora real, porque el promedio se calculó sobre casos cerrados | J2: Subestima la demora real, porque deja por fuera las peticiones aún abiertas | K2: c | L2: Al promediar solo lo cerrado, las peticiones más demoradas, que siguen abiertas, no entran en el cálculo y el promedio queda mejor de lo que es. | M2: Decir que refleja la realidad ignora las 1.400 abiertas; decir que la sobrestima invierte el sentido del sesgo. | O2: SI | P2: comun | Q2: no
